Workbook

Sheet 견적서
A1: 인 테 리 어 공 사 견 적 서
A2: EDGE COMPANY Co., Ltd. · INTERIOR ESTIMATE
B4: 고 객 명 | E4: 고객님 귀하
B5: 현장 주소
B6: 공 사 명 | C6: 아파트 32평형 전체 리모델링 공사
B7: 공사 규모 | C7: 공급 105㎡(32평형) / 전용 84㎡ · 확장형 · 방3 · 욕실2 · 천장고 2.3m
B8: 공사 기간 | C8: 착공 후 6주 (작업일 36일, 일요일·공휴일 휴무)
B9: 견적 번호 | C9: EC-INT-20261018-01 (견적일 2026. 10. 18)
B10: 유효 기간 | C10: 2026. 11. 17 (견적일로부터 30일)
A12: 공 급 자
B13: 상 호 | C13: ㈜엣지컴퍼니
B14: 대표이사 | C14: 고 진 식 (인)
B15: 사업자등록번호 | C15: 508-81-42798
B16: 주 소 | C16: 울산광역시 울주군 청량읍 온산로 615-1, 2·3층
B17: 대표번호 | C17: 1533-3210
B18: 면 허 | C18: 실내건축공사업 · 전기공사업(제 울산-00821호)
B20: 총 견적금액 (부가세 포함) | C20: 일금 오천만원정 | D20: =D45
B21: ="공급가액 "&TEXT(D43,"#,##0")&"원 + 부가가치세 "&TEXT(D44,"#,##0")&"원"
A23: 아래와 같이 견적합니다.
A25: No | B25: 공 종 | C25: 주요 내용 | D25: 금액(원) | E25: 구성비 | F25: 비 고
A26: 01 | B26: 가설·보양·철거공사 | C26: 공사신고·보양, 바닥·욕실·주방 철거, 폐기물 처리 | D26: ='상세내역'!G17 | E26: =IF($D$39=0,0,D26/$D$39)
A27: 02 | B27: 설비공사 | C27: 배관 압력시험, 주방·세탁실·욕실 배관 | D27: ='상세내역'!G23 | E27: =IF($D$39=0,0,D27/$D$39)
A28: 03 | B28: 목공사 | C28: 천장 평탄화, 무몰딩, 간접조명·커튼박스 | D28: ='상세내역'!G32 | E28: =IF($D$39=0,0,D28/$D$39)
A29: 04 | B29: 전기·조명공사 | C29: 분전반·배선, 스위치·콘센트, LED 조명 (면허 직영) | D29: ='상세내역'!G44 | E29: =IF($D$39=0,0,D29/$D$39) | F29: 면허 직영
A30: 05 | B30: 욕실공사 (2개소) | C30: 방수·타일·도기·수전·천장재 (공용·안방) | D30: ='상세내역'!G61 | E30: =IF($D$39=0,0,D30/$D$39)
A31: 06 | B31: 주방공사 | C31: ㄱ자 싱크대·엔지니어드스톤 상판·후드·벽타일 | D31: ='상세내역'!G73 | E31: =IF($D$39=0,0,D31/$D$39)
A32: 07 | B32: 바닥공사 | C32: 강마루 84㎡·레벨링·걸레받이 | D32: ='상세내역'!G78 | E32: =IF($D$39=0,0,D32/$D$39)
A33: 08 | B33: 도배공사 | C33: 벽·천장 실크벽지 | D33: ='상세내역'!G83 | E33: =IF($D$39=0,0,D33/$D$39)
A34: 09 | B34: 필름·도장공사 | C34: 방문·현관문 필름, 도어 하드웨어, 발코니 탄성코트 | D34: ='상세내역'!G89 | E34: =IF($D$39=0,0,D34/$D$39)
A35: 10 | B35: 타일공사 | C35: 현관·세탁실·다용도실 바닥 | D35: ='상세내역'!G94 | E35: =IF($D$39=0,0,D35/$D$39)
A36: 11 | B36: 중문공사 | C36: 현관 3연동 슬림 중문 | D36: ='상세내역'!G97 | E36: =IF($D$39=0,0,D36/$D$39)
A37: 12 | B37: 가구공사 | C37: 현관 신발장, 안방 붙박이장 | D37: ='상세내역'!G101 | E37: =IF($D$39=0,0,D37/$D$39)
A38: 13 | B38: 마감·청소 | C38: 실리콘, 입주청소, 준공 점검 | D38: ='상세내역'!G106 | E38: =IF($D$39=0,0,D38/$D$39)
B39: 직접공사비 계 | D39: =SUM(D26:D38) | E39: =SUM(E26:E38)
B40: 공과잡비·현장관리비 (소모자재·양중·주차·현장관리) | D40: =ROUND(D39*E40,-3) | E40: 0.05 | F40: 직접공사비 × 요율
B41: 소 계 | D41: =D39+D40
B42: 단수 정리 | D42: -186455
B43: 공급가액 | D43: =D41+D42
B44: 부가가치세 (10%) | D44: =ROUND(D43/10,0)
B45: 총 견적금액 (부가세 포함) | D45: =D43+D44
...

Sheet 상세내역
A1: 상 세 내 역 서
A2: 산출 기준 — 확장형 32평형 · 천장고 2.3m · 마루 84㎡(약 25.4평) · 벽 도배 210㎡ · 천장 도배 86㎡ · 욕실 2개소(공용=욕조형, 안방=샤워부스형) · 샷시(창호)는 기존 유지
A3: 단가 = 자재비 + 시공비 + 운반비 포함. 파란 글씨(수량·단가)를 고치면 금액·소계·견적서 합계가 자동으로 바뀝니다.
A4: No | B4: 품 명 | C4: 규격 · 사양 | D4: 단위 | E4: 수량 | F4: 단가(원) | G4: 금액(원) | H4: 비 고
A5: 01 | B5: 가설·보양·철거공사
A6: 01-01 | B6: 실측·디자인 상담 | C6: 평면 레이아웃·자재 샘플 컨펌, 착공 전 2회 | D6: 식 | E6: 1 | F6: 0 | G6: =ROUND(E6*F6,0) | H6: 무상 제공
A7: 01-02 | B7: 공사 신고·입주민 동의 | C7: 관리사무소 공사신고, 동의서 징구, 안내문 게시 | D7: 식 | E7: 1 | F7: 0 | G7: =ROUND(E7*F7,0) | H7: 무상 대행
A8: 01-03 | B8: 엘리베이터·공용부 보양 | C8: EV 내부 보양재, 복도·세대 앞 바닥 보호 | D8: 식 | E8: 1 | F8: 280000 | G8: =ROUND(E8*F8,0)
A9: 01-04 | B9: 실내 보양 | C9: 샷시·창호·현관문·유지 설비 보양(PE폼·골판지) | D9: 식 | E9: 1 | F9: 300000 | G9: =ROUND(E9*F9,0)
A10: 01-05 | B10: 바닥재 철거 | C10: 기존 강마루 철거, 바닥 본드 그라인딩 | D10: ㎡ | E10: 84 | F10: 9500 | G10: =ROUND(E10*F10,0)
A11: 01-06 | B11: 욕실 철거 | C11: 벽·바닥 타일, 도기, 천장재, 욕조 철거 | D11: 개소 | E11: 2 | F11: 480000 | G11: =ROUND(E11*F11,0) | H11: 공용·안방
A12: 01-07 | B12: 주방가구 철거 | C12: 상·하부장, 상판, 후드 | D12: 식 | E12: 1 | F12: 200000 | G12: =ROUND(E12*F12,0)
A13: 01-08 | B13: 몰딩·문선·걸레받이 철거 | C13: 무몰딩 마감 대비 전 실 | D13: 식 | E13: 1 | F13: 220000 | G13: =ROUND(E13*F13,0)
A14: 01-09 | B14: 신발장·붙박이장 철거 | C14: 현관 신발장, 안방 붙박이장 | D14: 식 | E14: 1 | F14: 150000 | G14: =ROUND(E14*F14,0)
A15: 01-10 | B15: 현관 바닥 타일 철거 | C15: 기존 타일·몰탈 제거 | D15: 식 | E15: 1 | F15: 80000 | G15: =ROUND(E15*F15,0)
A16: 01-11 | B16: 폐기물 반출·처리 | C16: 1톤 차량, 허가 처리업체 위탁 | D16: 대 | E16: 3 | F16: 280000 | G16: =ROUND(E16*F16,0)
A17: 가설·보양·철거공사 소계 | G17: =SUM(G6:G16)
A18: 02 | B18: 설비공사
A19: 02-01 | B19: 급수·난방 배관 압력시험 | C19: 철거 후 누수 점검, 결과 사진 보고 | D19: 식 | E19: 1 | F19: 100000 | G19: =ROUND(E19*F19,0)
A20: 02-02 | B20: 주방 급·배수 배관 정리 | C20: 싱크 위치 기준 냉·온수·배수 연장 | D20: 식 | E20: 1 | F20: 350000 | G20: =ROUND(E20*F20,0)
A21: 02-03 | B21: 세탁실 수전·배수 교체 | C21: 세탁기 전용 수전, 배수트랩 | D21: 식 | E21: 1 | F21: 150000 | G21: =ROUND(E21*F21,0)
A22: 02-04 | B22: 욕실 배관 부분 교체 | C22: 노후 급수 분기관·배수트랩 교체 | D22: 개소 | E22: 2 | F22: 120000 | G22: =ROUND(E22*F22,0)
A23: 설비공사 소계 | G23: =SUM(G19:G22)
A24: 03 | B24: 목공사
A25: 03-01 | B25: 천장 평탄화·보강 | C25: 거실·주방, 석고보드 9.5T 덧방 + 각재 보강 | D25: ㎡ | E25: 40 | F25: 30000 | G25: =ROUND(E25*F25,0)
A26: 03-02 | B26: 무몰딩 마감 | C26: 전 실 천장-벽 경계, 마감비드 + 퍼티 | D26: m | E26: 95 | F26: 10000 | G26: =ROUND(E26*F26,0)
A27: 03-03 | B27: 거실 우물천장 간접조명 박스 | C27: 각재 + 석고보드 2겹, LED 매입 홈 | D27: m | E27: 18 | F27: 55000 | G27: =ROUND(E27*F27,0)
A28: 03-04 | B28: 매입형 커튼박스 | C28: W150, 거실·안방·침실2·침실3 | D28: m | E28: 14 | F28: 48000 | G28: =ROUND(E28*F28,0) | H28: 전동커튼 대응
A29: 03-05 | B29: 슬림 문선 교체 | C29: 방문 5·욕실 2, 무문선 스타일 | D29: 개소 | E29: 7 | F29: 65000 | G29: =ROUND(E29*F29,0)
A30: 03-06 | B30: 주방 상부 막음·가구 하지 | C30: 상부장 상단 막음, 후드 덕트 마감 | D30: 식 | E30: 1 | F30: 250000 | G30: =ROUND(E30*F30,0)
A31: 03-07 | B31: 목공 부자재·양중 | C31: 타카·본드·자재 운반 | D31: 식 | E31: 1 | F31: 200000 | G31: =ROUND(E31*F31,0)
A32: 목공사 소계 | G32: =SUM(G25:G31)
A33: 04 | B33: 전기·조명공사
A34: 04-01 | B34: 분전반 정비 | C34: 메인 누전차단기 교체, 분기 회로 재배분 | D34: 식 | E34: 1 | F34: 420000 | G34: =ROUND(E34*F34,0)
A35: 04-02 | B35: 배선 증설·교체 | C35: 인덕션 전용회로 신설, 조명 회로 분리 | D35: 식 | E35: 1 | F35: 550000 | G35: =ROUND(E35*F35,0)
A36: 04-03 | B36: 스위치·콘센트 전체 교체 | C36: 와이드 스위치, 매입 콘센트(USB형 일부) | D36: 개 | E36: 56 | F36: 19000 | G36: =ROUND(E36*F36,0)
A37: 04-04 | B37: LED 다운라이트 | C37: 3인치 매입형 10W, 색온도 선택(3000K/4000K), 타공·결선 | D37: 개 | E37: 30 | F37: 40000 | G37: =ROUND(E37*F37,0)
A38: 04-05 | B38: LED 간접 라인조명 | C38: 거실 우물천장, 현관 신발장 하부 | D38: m | E38: 20 | F38: 28000 | G38: =ROUND(E38*F38,0)
A39: 04-06 | B39: 침실 LED 방등 | C39: 슬림 엣지형 50W | D39: 개 | E39: 3 | F39: 90000 | G39: =ROUND(E39*F39,0)
A40: 04-07 | B40: 식탁 펜던트 조명 | C40: 2등, 결선 포함 | D40: 식 | E40: 1 | F40: 250000 | G40: =ROUND(E40*F40,0)
...

Sheet 공정표
A1: 공 정 표 — 6주 (작업일 36일 · 주 6일 작업, 일요일·공휴일 휴무)
A2: 착공일 (월요일) | B2: 46328 | C2: ← 착공일을 입력하면 아래 날짜가 바뀝니다 (예시 날짜)
A4: 공 정 | B4: 세부 내용 | C4: 일수 | D4: 1주차 | J4: 2주차 | P4: 3주차 | V4: 4주차 | AB4: 5주차 | AH4: 6주차
D5: D1 | E5: D2 | F5: D3 | G5: D4 | H5: D5 | I5: D6 | J5: D7 | K5: D8 | L5: D9 | M5: D10 | N5: D11 | O5: D12 | P5: D13 | Q5: D14 | R5: D15 | S5: D16 | T5: D17 | U5: D18 | V5: D19 | W5: D20 | X5: D21 | Y5: D22 | Z5: D23 | AA5: D24 | AB5: D25 | AC5: D26 | AD5: D27 | AE5: D28 | AF5: D29 | AG5: D30 | AH5: D31 | AI5: D32 | AJ5: D33 | AK5: D34 | AL5: D35 | AM5: D36
D6: 월 | E6: 화 | F6: 수 | G6: 목 | H6: 금 | I6: 토 | J6: 월 | K6: 화 | L6: 수 | M6: 목 | N6: 금 | O6: 토 | P6: 월 | Q6: 화 | R6: 수 | S6: 목 | T6: 금 | U6: 토 | V6: 월 | W6: 화 | X6: 수 | Y6: 목 | Z6: 금 | AA6: 토 | AB6: 월 | AC6: 화 | AD6: 수 | AE6: 목 | AF6: 금 | AG6: 토 | AH6: 월 | AI6: 화 | AJ6: 수 | AK6: 목 | AL6: 금 | AM6: 토
A7: 날짜 | D7: =$B$2+0+INT(0/6) | E7: =$B$2+1+INT(1/6) | F7: =$B$2+2+INT(2/6) | G7: =$B$2+3+INT(3/6) | H7: =$B$2+4+INT(4/6) | I7: =$B$2+5+INT(5/6) | J7: =$B$2+6+INT(6/6) | K7: =$B$2+7+INT(7/6) | L7: =$B$2+8+INT(8/6) | M7: =$B$2+9+INT(9/6) | N7: =$B$2+10+INT(10/6) | O7: =$B$2+11+INT(11/6) | P7: =$B$2+12+INT(12/6) | Q7: =$B$2+13+INT(13/6) | R7: =$B$2+14+INT(14/6) | S7: =$B$2+15+INT(15/6) | T7: =$B$2+16+INT(16/6) | U7: =$B$2+17+INT(17/6) | V7: =$B$2+18+INT(18/6) | W7: =$B$2+19+INT(19/6) | X7: =$B$2+20+INT(20/6) | Y7: =$B$2+21+INT(21/6) | Z7: =$B$2+22+INT(22/6) | AA7: =$B$2+23+INT(23/6) | AB7: =$B$2+24+INT(24/6) | AC7: =$B$2+25+INT(25/6) | AD7: =$B$2+26+INT(26/6) | AE7: =$B$2+27+INT(27/6) | AF7: =$B$2+28+INT(28/6) | AG7: =$B$2+29+INT(29/6) | AH7: =$B$2+30+INT(30/6) | AI7: =$B$2+31+INT(31/6) | AJ7: =$B$2+32+INT(32/6) | AK7: =$B$2+33+INT(33/6) | AL7: =$B$2+34+INT(34/6) | AM7: =$B$2+35+INT(35/6)
A8: 보양·공사 준비 | B8: EV·공용부·실내 보양, 공사 안내문 게시 | C8: 1
A9: 철거 | B9: 바닥·욕실·주방·몰딩 철거, 폐기물 반출 | C9: 3
A10: 설비 | B10: 배관 압력시험, 주방·세탁실 배관 정리 | C10: 2
A11: 전기 1차 | B11: 분전반 정비, 배선 증설·입선, 타공 위치 표시 | C11: 3
A12: 욕실 방수 | B12: 액체방수 2회 → 담수 테스트 48시간 | C12: 4
A13: 목공 | B13: 천장 평탄화, 무몰딩, 간접조명·커튼박스, 문선 | C13: 6
A14: 욕실 타일 | B14: 벽·바닥 타일, 젠다이·문턱 | C14: 5
A15: 필름 | B15: 방문·문틀·현관문 필름 | C15: 3
A16: 타일·도장 | B16: 현관·세탁실 타일, 발코니 탄성코트 | C16: 3
A17: 욕실 마감 | B17: 천장재, 도기·수전·욕실장 설치 | C17: 2
A18: 도배 | B18: 퍼티·초배 → 벽·천장 실크벽지 | C18: 4
A19: 바닥 | B19: 강마루 시공, 걸레받이 | C19: 3
... A27: 준공·인도 | B27: 잔금, A/S 보증서 발급, 사용 설명 | C27: 1
A28: ★ 고객 확인 | B28: 현장 확인·승인 시점 (아래 표 참고) | F28: ★ | K28: ★ | O28: ★ | X28: ★ | AJ28: ★ | AM28: ★
A29: ₩ 결제 | B29: D1 착공금 30% · D12 중도금 40% · D36 잔금 20% | D29: ₩ | O29: ₩ | AM29: ₩
A31: 범 례 | B31: ■ 가설·철거 ■ 설비·전기 ■ 방수·타일·욕실 ■ 목공·가구 ■ 필름·도배·바닥 ■ 청소·준공
A33: 시 점 | B33: 고객 확인 포인트
A34: 착공 전 | B34: 디자인·자재 샘플 최종 확정 — 마루·벽지·타일·필름·싱크대 도어 색상
A35: D3 | B35: 철거 완료 현장 확인 — 배관·바닥 상태, 숨은 하자 발견 시 사진 공유 후 서면 합의
A36: D8 | B36: 욕실 담수 테스트 결과 확인 — 48시간 누수 없음 사진·영상 보고
A37: D12 | B37: 목공 완료 — 조명·스위치·콘센트 위치 현장 최종 확인 (중도금 시점)
A38: D21 | B38: 도배 완료 — 벽지 들뜸·이음 상태 확인
A39: D33 | B39: 고객 동행 점검 — 지적 사항 목록(펀치리스트) 작성
A40: D36 | B40: 준공·인도 — 잔금, A/S 보증서 발급

Sheet 선택공사
A1: 선 택 공 사 (견적 금액 미포함 · 참고 예상가)
A2: 착공 전에 결정하시면 배선·보강·일정에 미리 반영합니다. 금액은 실측·제품 선택 후 확정됩니다.
A4: No | B4: 항 목 | C4: 내 용 | D4: 참고 예상가 | E4: 비 고
A5: 1 | B5: 샷시(창호) 전체 교체 | C5: 이중창 전체 교체, LX·KCC 동급 (확장형 32평) | D5: 약 1,400만 ~ 1,800만원 | E5: 실측 후 확정 · 착공 전 결정
A6: 2 | B6: 시스템에어컨 | C6: 거실 + 침실 3 (총 4대), 천장 매립 배관 | D6: 약 850만 ~ 1,100만원 | E6: 제조사 견적 기준 · 목공 전 결정
A7: 3 | B7: 커튼·블라인드 | C7: 거실 전동커튼 + 침실 암막커튼·블라인드 | D7: 약 250만 ~ 400만원 | E7: 엣지리브커튼 · 커튼박스·전원 반영됨
A8: 4 | B8: 거실 실링팬 | C8: 천장 보강 + 전원 인출 + 설치 | D8: 설치비 15만원 + 제품가 | E8: 아크로 실링팬 · 목공 단계 결정
A9: 5 | B9: 방문 교체 | C9: 필름 대신 ABS 도어 교체 (방문 5짝) | D9: 필름 대비 +약 80만 ~ 120만원
A10: 6 | B10: 줄눈 시공 | C10: 욕실 2개소 · 현관 (에폭시계) | D10: 약 60만 ~ 90만원 | E10: 타일 시공 후 진행
A11: 7 | B11: 거실 아트월 | C11: 포세린 대형 타일 600×1200 | D11: 약 150만 ~ 220만원
A12: 8 | B12: 디지털 도어록 | C12: 현관 푸시풀 타입 교체 | D12: 약 35만 ~ 50만원
A13: 9 | B13: 드레스룸 시스템 선반 | C13: 안방 드레스룸 | D13: 약 80만 ~ 130만원

Sheet 계약조건
A1: 결 제 조 건 · 특 기 사 항
A3: 단 계 | B3: 시 점 | C3: 비 율 | D3: 금액(원)
A4: 계약금 | B4: 계약 체결 시 | C4: 0.1 | D4: =ROUND('견적서'!$D$45*C4,0)
A5: 착공금 | B5: 착공일 (D1) | C5: 0.3 | D5: =ROUND('견적서'!$D$45*C5,0)
A6: 중도금 | B6: 목공 완료 후 (D12) | C6: 0.4 | D6: =ROUND('견적서'!$D$45*C6,0)
A7: 잔금 | B7: 준공 점검·보수 완료 후 (D36) | C7: 0.2 | D7: =ROUND('견적서'!$D$45*C7,0)
A8: 합 계 | C8: =SUM(C4:C7) | D8: =SUM(D4:D7)
A10: 포함 사항
A11: · 내역서에 기재된 전 공종의 자재비·시공비·운반비·폐기물 처리비
A12: · 관리사무소 공사 신고·입주민 동의서 대행, 엘리베이터·공용부 보양
A13: · 공정별 시공 사진·영상 보고 (주 2회 이상, 카카오톡)
A14: · 준공 전 전기 안전점검(절연저항 측정) 및 입주 청소
A16: 불포함 사항
A17: · 샷시(창호), 가전(인덕션·식기세척기·냉장고·에어컨), 커튼·블라인드 → 선택공사 참고
A18: · 고객 지정 수입 조명기구·수전·도기 등 사양 상향분 (차액 정산)
A19: · 철거 후 발견되는 숨은 하자 보수 — 배관 누수, 바닥 들뜸·크랙, 벽체 결로·곰팡이
A20: · 이사·짐 보관, 단지에서 부과하는 엘리베이터 사용료·공사 예치금
A22: 특기 사항
A23: 1. 본 견적은 확장형 32평형(공급 105㎡ / 전용 84㎡), 천장고 2.3m 기준이며 현장 실측 후 수량을 확정합니다. 실측 수량이 달라지면 내역서 단가로 정산합니다.
... A31: 하자보수 (준공일로부터 무상 A/S)
A32: 실내의장·목공·가구 | C32: 1년
A33: 도배·필름·도장 | C33: 1년
A34: 타일·바닥 | C34: 1년
A35: 전기·조명 | C35: 1년
A36: 방수 (욕실·발코니) | C36: 3년
A38: 위 견적 내용을 확인하였으며, 이에 따라 공사를 의뢰합니다. 20 년 월 일
A40: 고객 (갑) : (서명) | C40: 공급자 (을) : ㈜엣지컴퍼니 대표이사 고진식 (인)
